Workbook

Sheet Sheet1
A1: id | B1: slug | C1: name | D1: start_year | E1: end_year | F1: is_extant | G1: latitude | H1: longitude | I1: W3W | J1: architecture | K1: is_gmc | L1: notes
A2: 1 | B2: aeolus-view-camp | C2: Aeolus View Camp | D2: 1922 | E2: 1932 | F2: =NOT(ISNUMBER(E2)) -> FALSE | G2: 43.203333 | H2: -72.960156 | I2: =W3WCONVERTTO3WA(G2,H2) -> #ERROR! | K2: TRUE
A3: 2 | B3: aldrich-job-camp | C3: Aldrich Job Camp | D3: 1910 | E3: 1930 | F3: =NOT(ISNUMBER(E3)) -> FALSE | G3: 43.4105 | H3: -72.944497 | K3: FALSE
A4: 3 | B4: atlas-valley-shelter | C4: Atlas Valley Shelter | D4: 1967 | F4: =NOT(ISNUMBER(E4)) -> TRUE | G4: 44.912974 | H4: -72.504879 | I4: =W3WCONVERTTO3WA(G4,H4) -> #ERROR! | J4: Prefab shelter | K4: TRUE
A5: 4 | B5: badger-camp | C5: Badger Camp | D5: 1928 | E5: 1931 | F5: =NOT(ISNUMBER(E5)) -> FALSE | G5: 44.723194 | H5: -72.655229 | J5: Lumber Camp | K5: FALSE
A6: 5 | B6: bamforth-ridge | C6: Bamforth Ridge | D6: 2002 | F6: =NOT(ISNUMBER(E6)) -> TRUE | G6: 44.35056 | H6: -72.86218 | I6: =W3WCONVERTTO3WA(G6,H6) -> #ERROR! | J6: Log Lean-To | K6: TRUE
A7: 6 | B7: barnes-camp | C7: Barnes Camp | D7: 1927 | F7: =NOT(ISNUMBER(E7)) -> TRUE | G7: 44.533123 | H7: -72.788859 | I7: =W3WCONVERTTO3WA(G7,H7) -> #ERROR! | J7: Inn | K7: FALSE
A8: 7 | B8: barrows-camp | C8: Barrows Camp | D8: 1931 | E8: 1994 | F8: =NOT(ISNUMBER(E8)) -> FALSE | G8: 44.68949 | H8: -72.72429 | I8: =W3WCONVERTTO3WA(G8,H8) -> #ERROR! | J8: Buchanan | K8: TRUE
A9: 8 | B9: battell-lodge-1 | C9: Battell Lodge 1st | D9: 1899 | E9: 1917 | F9: =NOT(ISNUMBER(E9)) -> FALSE | G9: 44.111591 | H9: -72.936524 | J9: Log Cabin | K9: FALSE
A10: 9 | B10: battell-lodge-2 | C10: Battell Lodge 2nd | D10: 1926 | E10: 1937 | F10: =NOT(ISNUMBER(E10)) -> FALSE | J10: Log Lean-To | K10: TRUE
A11: 10 | B11: battell-shelter-1 | C11: Battell Shelter 1st | D11: 1938 | E11: 1966 | F11: =NOT(ISNUMBER(E11)) -> FALSE | G11: 44.111685 | H11: -72.936726 | J11: Adirondak | K11: TRUE
A12: 11 | B12: battell-shelter-2 | C12: Battell Shelter 2nd | D12: 1967 | F12: =NOT(ISNUMBER(E12)) -> TRUE | G12: 44.111685 | H12: -72.936726 | I12: =W3WCONVERTTO3WA(G12,H12) -> #ERROR! | J12: Wood Frame | K12: TRUE
A13: 12 | B13: beane-farm | C13: Beane Farm | D13: 1917 | E13: 1966 | F13: =NOT(ISNUMBER(E13)) -> FALSE | G13: 44.247986 | H13: -72.942034 | I13: =W3WCONVERTTO3WA(G13,H13) -> #ERROR! | J13: Private Home | K13: FALSE
A14: 13 | B14: bear-hollow-shelter | C14: Bear Hollow Shelter | D14: 1991 | F14: =NOT(ISNUMBER(E14)) -> TRUE | G14: 44.6047 | H14: -72.717016 | I14: =W3WCONVERTTO3WA(G14,H14) -> #ERROR! | J14: Wood Frame | K14: TRUE
A15: 14 | B15: beaver-meadow-cabin | C15: Beaver Meadow Cabin | D15: 1917 | E15: 1920 | F15: =NOT(ISNUMBER(E15)) -> FALSE | G15: 44.217624 | H15: -72.928989 | J15: Log Cabin | K15: FALSE | L15: On Monroe Skyline near Mollys Starks Balcony, shown on Monroe Skyline Map at GMCHQ
A16: 15 | B16: beaver-meadow-lodge | C16: Beaver Meadow Lodge | D16: 1947 | F16: =NOT(ISNUMBER(E16)) -> TRUE | G16: 44.568218 | H16: -72.742922 | I16: =W3WCONVERTTO3WA(G16,H16) -> #ERROR! | J16: Log Cabin | K16: TRUE
A17: 16 | B17: belvidere-mountain-foresters-cabin | C17: Belvidere Mountain Foresters Cabin | F17: FALSE | G17: 44.77337 | H17: -72.550935 | K17: FALSE
A18: 17 | B18: big-branch-shelter | C18: Big Branch Shelter | D18: 1963 | F18: =NOT(ISNUMBER(E18)) -> TRUE | G18: 43.364039 | H18: -72.945972 | I18: =W3WCONVERTTO3WA(G18,H18) -> #ERROR! | J18: Wood Frame | K18: TRUE
A19: 18 | B19: bigelow-shelter | C19: Bigelow Shelter | D19: 1961 | E19: 1997 | F19: =NOT(ISNUMBER(E19)) -> FALSE | G19: 43.10202 | H19: -72.96649 | I19: =W3WCONVERTTO3WA(G19,H19) -> #ERROR! | K19: TRUE
A20: 19 | B20: birch-glen-camp | C20: Birch Glen Camp | D20: 1930 | F20: =NOT(ISNUMBER(E20)) -> TRUE | G20: 44.236676 | H20: -72.930401 | I20: =W3WCONVERTTO3WA(G20,H20) -> #ERROR! | K20: TRUE
A21: 20 | B21: birch-glen-lodge | C21: Birch Glen Lodge | D21: 1913 | E21: 1930 | F21: =NOT(ISNUMBER(E21)) -> FALSE | G21: 44.236676 | H21: -72.930401 | K21: TRUE
A22: 21 | B22: blowdown-camp | C22: Blowdown Camp | D22: 1924 | E22: 1929 | F22: =NOT(ISNUMBER(E22)) -> FALSE | G22: 43.958735 | H22: -72.968788 | J22: Lumber Camp | K22: FALSE | L22: Loggers
A23: 22 | B23: blue-triangle-camp | C23: Blue Triangle Camp | D23: 1930 | E23: 1949 | F23: =NOT(ISNUMBER(E23)) -> FALSE | G23: 43.565 | H23: -72.847338 | J23: YMCA Canp | K23: TRUE
A24: 24 | B24: bolton-lodge | C24: Bolton Lodge | D24: 1928 | F24: =NOT(ISNUMBER(E24)) -> TRUE | G24: 44.414236 | H24: -72.869638 | I24: =W3WCONVERTTO3WA(G24,H24) -> #ERROR! | J24: Stone | K24: TRUE
A25: 25 | B25: bourn-pond-camp | C25: Bourn Pond Camp | F25: FALSE | G25: 43.103556 | H25: -73.005533 | I25: =W3WCONVERTTO3WA(G25,H25) -> #ERROR! | K25: FALSE
A26: 26 | B26: bourn-pond-shelter-north | C26: North Bourn Pond Shelter | D26: 1965 | E26: 1983 | F26: =NOT(ISNUMBER(E26)) -> FALSE | G26: 43.109808 | H26: -73.00067 | I26: =W3WCONVERTTO3WA(G26,H26) -> #ERROR! | J26: Wooden Frame Shelter | K26: TRUE | L26: NBP Tenting area replaced shelter until 2011 GB
A27: 27 | B27: bourn-pond-shelter-south | C27: South Bourn Pond Shelter | D27: 1957 | E27: 2005 | F27: =NOT(ISNUMBER(E27)) -> FALSE | G27: 43.103556 | H27: -73.005533 | I27: =W3WCONVERTTO3WA(G27,H27) -> #ERROR! | J27: Log Shelter | K27: TRUE | L27: Reconstructed from log fishing camps by Putney Summer Work Camp
A28: 28 | B28: bourn-pond-tenting-areas | C28: Bourn Pond Tenting Areas | D28: 1983 | F28: =NOT(ISNUMBER(E28)) -> TRUE | G28: 43.108142 | H28: -73.002863 | I28: =W3WCONVERTTO3WA(G28,H28) -> #ERROR! | J28: Tenting Area | K28: TRUE
A29: 29 | B29: boyce-shelter-1 | C29: Boyce Shelter 1st | D29: 1926 | E29: 1941 | F29: =NOT(ISNUMBER(E29)) -> FALSE | G29: 43.966863 | H29: -72.94786 | I29: =W3WCONVERTTO3WA(G29,H29) -> #ERROR! | J29: Log Lean-To | K29: TRUE
A30: 30 | B30: boyce-shelter-2 | C30: Boyce Shelter 2nd | D30: 1941 | E30: 1963 | F30: =NOT(ISNUMBER(E30)) -> FALSE | G30: 43.966863 | H30: -72.94786 | I30: =W3WCONVERTTO3WA(G30,H30) -> #ERROR! | J30: Adirondak | K30: TRUE
A31: 31 | B31: boyce-shelter-3 | C31: Boyce Shelter 3rd | D31: 1963 | F31: =NOT(ISNUMBER(E31)) -> TRUE | G31: 43.966863 | H31: -72.94786 | I31: =W3WCONVERTTO3WA(G31,H31) -> #ERROR! | J31: Wood Frame | K31: TRUE
A32: 32 | B32: bread-loaf-inn | C32: Bread Loaf Inn | D32: 1861 | F32: =NOT(ISNUMBER(E32)) -> TRUE | G32: 43.95395 | H32: -72.9933 | I32: =W3WCONVERTTO3WA(G32,H32) -> #ERROR! | J32: Inn | K32: FALSE
A33: 33 | B33: bread-loaf-shelter | C33: Bread Loaf Shelter | D33: 1931 | E33: 1960 | F33: =NOT(ISNUMBER(E33)) -> FALSE | G33: 44.000138 | H33: -72.931148 | J33: Log Lean-To | K33: TRUE
A34: 34 | B34: bromley-camp | C34: Bromley Camp | D34: 1955 | E34: 1984 | F34: =NOT(ISNUMBER(E34)) -> FALSE | G34: 43.2148 | H34: -72.9651 | I34: =W3WCONVERTTO3WA(G34,H34) -> #ERROR! | J34: Buchanan | K34: TRUE
A35: 35 | B35: bromley-lodge | C35: Bromley Lodge | D35: 1933 | E35: 1951 | F35: =NOT(ISNUMBER(E35)) -> FALSE | G35: 43.2148 | H35: -72.9651 | K35: TRUE
A36: 36 | B36: bromley-shelter | C36: Bromley Shelter | D36: 2003 | F36: =NOT(ISNUMBER(E36)) -> TRUE | G36: 43.222469 | H36: -72.95047 | I36: =W3WCONVERTTO3WA(G36,H36) -> #ERROR! | J36: Post and Beam | K36: TRUE | L36: Erik and Laurel Tobiason
A37: 37 | B37: bromley-tenting-area | C37: Bromley Tenting Area | D37: 1985 | E37: 2003 | F37: =NOT(ISNUMBER(E37)) -> FALSE | G37: 43.2148 | H37: -72.9651 | J37: Tenting Area | K37: TRUE
A38: 38 | B38: brushs-farm | C38: Brush's Farm | E38: 1928 | F38: =NOT(ISNUMBER(E38)) -> FALSE | G38: 44.371324 | H38: -72.87976 | J38: Private Home | K38: FALSE
A39: 39 | B39: bryant-cabin | C39: Bryant Cabin | D39: 1930 | F39: =NOT(ISNUMBER(E39)) -> TRUE | G39: 44.43256 | H39: -72.8418 | I39: =W3WCONVERTTO3WA(G39,H39) -> #ERROR! | K39: TRUE
A40: 40 | B40: buchanan-lodge | C40: Buchanan Lodge | D40: 1964 | E40: 1978 | F40: =NOT(ISNUMBER(E40)) -> FALSE | G40: 44.360572 | H40: -72.876468 | J40: Frame cabin | K40: TRUE
...

Sheet Sheet2
B1: name | C1: ', | D1: start_year | F1: end_year | G1: ', | H1: is_gmc | I1: ,' | J1: architecture | K1: ',' | L1: notes
A2: update shelters set name=' | B2: =Sheet1!C2 -> Aeolus View Camp | C2: ', start_year= | D2: =Sheet1!D2 -> 1922 | E2: , end_year= | F2: =Sheet1!E2 -> 1932 | G2: , is_gmc= | H2: =IF(Sheet1!K2, 1, 0) -> 1 | I2: , architecture=' | J2: =Sheet1!J2 | K2: ', notes=' | L2: =Sheet1!L2 | M2: ' where shelter_key=' | N2: =Sheet1!B2 -> aeolus-view-camp | O2: '
A3: update shelters set name=' | B3: =Sheet1!C3 -> Aldrich Job Camp | C3: ', start_year= | D3: =Sheet1!D3 -> 1910 | E3: , end_year= | F3: =Sheet1!E3 -> 1930 | G3: , is_gmc= | H3: =IF(Sheet1!K3, 1, 0) -> 0 | I3: , architecture=' | J3: =Sheet1!J3 | K3: ', notes=' | L3: =Sheet1!L3 | M3: ' where shelter_key=' | N3: =Sheet1!B3 -> aldrich-job-camp | O3: '
A4: update shelters set name=' | B4: =Sheet1!C4 -> Atlas Valley Shelter | C4: ', start_year= | D4: =Sheet1!D4 -> 1967 | E4: , end_year= | F4: =Sheet1!E4 | G4: , is_gmc= | H4: =IF(Sheet1!K4, 1, 0) -> 1 | I4: , architecture=' | J4: =Sheet1!J4 -> Prefab shelter | K4: ', notes=' | L4: =Sheet1!L4 | M4: ' where shelter_key=' | N4: =Sheet1!B4 -> atlas-valley-shelter | O4: '
A5: update shelters set name=' | B5: =Sheet1!C5 -> Badger Camp | C5: ', start_year= | D5: =Sheet1!D5 -> 1928 | E5: , end_year= | F5: =Sheet1!E5 -> 1931 | G5: , is_gmc= | H5: =IF(Sheet1!K5, 1, 0) -> 0 | I5: , architecture=' | J5: =Sheet1!J5 -> Lumber Camp | K5: ', notes=' | L5: =Sheet1!L5 | M5: ' where shelter_key=' | N5: =Sheet1!B5 -> badger-camp | O5: '
A6: update shelters set name=' | B6: =Sheet1!C6 -> Bamforth Ridge | C6: ', start_year= | D6: =Sheet1!D6 -> 2002 | E6: , end_year= | F6: =Sheet1!E6 | G6: , is_gmc= | H6: =IF(Sheet1!K6, 1, 0) -> 1 | I6: , architecture=' | J6: =Sheet1!J6 -> Log Lean-To | K6: ', notes=' | L6: =Sheet1!L6 | M6: ' where shelter_key=' | N6: =Sheet1!B6 -> bamforth-ridge | O6: '
A7: update shelters set name=' | B7: =Sheet1!C7 -> Barnes Camp | C7: ', start_year= | D7: =Sheet1!D7 -> 1927 | E7: , end_year= | F7: =Sheet1!E7 | G7: , is_gmc= | H7: =IF(Sheet1!K7, 1, 0) -> 0 | I7: , architecture=' | J7: =Sheet1!J7 -> Inn | K7: ', notes=' | L7: =Sheet1!L7 | M7: ' where shelter_key=' | N7: =Sheet1!B7 -> barnes-camp | O7: '
A8: update shelters set name=' | B8: =Sheet1!C8 -> Barrows Camp | C8: ', start_year= | D8: =Sheet1!D8 -> 1931 | E8: , end_year= | F8: =Sheet1!E8 -> 1994 | G8: , is_gmc= | H8: =IF(Sheet1!K8, 1, 0) -> 1 | I8: , architecture=' | J8: =Sheet1!J8 -> Buchanan | K8: ', notes=' | L8: =Sheet1!L8 | M8: ' where shelter_key=' | N8: =Sheet1!B8 -> barrows-camp | O8: '
A9: update shelters set name=' | B9: =Sheet1!C9 -> Battell Lodge 1st | C9: ', start_year= | D9: =Sheet1!D9 -> 1899 | E9: , end_year= | F9: =Sheet1!E9 -> 1917 | G9: , is_gmc= | H9: =IF(Sheet1!K9, 1, 0) -> 0 | I9: , architecture=' | J9: =Sheet1!J9 -> Log Cabin | K9: ', notes=' | L9: =Sheet1!L9 | M9: ' where shelter_key=' | N9: =Sheet1!B9 -> battell-lodge-1 | O9: '
A10: update shelters set name=' | B10: =Sheet1!C10 -> Battell Lodge 2nd | C10: ', start_year= | D10: =Sheet1!D10 -> 1926 | E10: , end_year= | F10: =Sheet1!E10 -> 1937 | G10: , is_gmc= | H10: =IF(Sheet1!K10, 1, 0) -> 1 | I10: , architecture=' | J10: =Sheet1!J10 -> Log Lean-To | K10: ', notes=' | L10: =Sheet1!L10 | M10: ' where shelter_key=' | N10: =Sheet1!B10 -> battell-lodge-2 | O10: '
A11: update shelters set name=' | B11: =Sheet1!C11 -> Battell Shelter 1st | C11: ', start_year= | D11: =Sheet1!D11 -> 1938 | E11: , end_year= | F11: =Sheet1!E11 -> 1966 | G11: , is_gmc= | H11: =IF(Sheet1!K11, 1, 0) -> 1 | I11: , architecture=' | J11: =Sheet1!J11 -> Adirondak | K11: ', notes=' | L11: =Sheet1!L11 | M11: ' where shelter_key=' | N11: =Sheet1!B11 -> battell-shelter-1 | O11: '
A12: update shelters set name=' | B12: =Sheet1!C12 -> Battell Shelter 2nd | C12: ', start_year= | D12: =Sheet1!D12 -> 1967 | E12: , end_year= | F12: =Sheet1!E12 | G12: , is_gmc= | H12: =IF(Sheet1!K12, 1, 0) -> 1 | I12: , architecture=' | J12: =Sheet1!J12 -> Wood Frame | K12: ', notes=' | L12: =Sheet1!L12 | M12: ' where shelter_key=' | N12: =Sheet1!B12 -> battell-shelter-2 | O12: '
A13: update shelters set name=' | B13: =Sheet1!C13 -> Beane Farm | C13: ', start_year= | D13: =Sheet1!D13 -> 1917 | E13: , end_year= | F13: =Sheet1!E13 -> 1966 | G13: , is_gmc= | H13: =IF(Sheet1!K13, 1, 0) -> 0 | I13: , architecture=' | J13: =Sheet1!J13 -> Private Home | K13: ', notes=' | L13: =Sheet1!L13 | M13: ' where shelter_key=' | N13: =Sheet1!B13 -> beane-farm | O13: '
... A286: update shelters set name=' | B286: =Sheet1!C286 | C286: ', start_year= | D286: =Sheet1!D286 | E286: , end_year= | F286: =Sheet1!E286 | G286: , is_gmc= | H286: =IF(Sheet1!K286, 1, 0) -> 0 | I286: , architecture=' | J286: =Sheet1!J286 | K286: ', notes=' | L286: =Sheet1!L286 | M286: ' where shelter_key=' | N286: =Sheet1!B286 | O286: '
A287: (' | B287: =Sheet1!C289 | C287: ', | G287: ', | H287: =IF(Sheet1!K295, 1, 0) -> 0 | I287: ,' | K287: ',' | M287: ','
A288: (' | B288: =Sheet1!C290 | C288: ', | G288: ', | H288: =IF(Sheet1!K296, 1, 0) -> 0 | I288: ,' | K288: ',' | M288: ','
A289: (' | B289: =Sheet1!C291 | C289: ', | G289: ', | H289: =IF(Sheet1!K297, 1, 0) -> 0 | I289: ,' | K289: ',' | M289: ','
A290: (' | B290: =Sheet1!C292 | C290: ', | G290: ', | H290: =IF(Sheet1!K298, 1, 0) -> 0 | I290: ,' | K290: ',' | M290: ','
A291: (' | B291: =Sheet1!C293 | C291: ', | G291: ', | H291: =IF(Sheet1!K299, 1, 0) -> 0 | I291: ,' | K291: ',' | M291: ','
A292: (' | C292: ', | G292: ', | H292: =IF(Sheet1!K300, 1, 0) -> 0 | I292: ,' | K292: ',' | M292: ','
A293: (' | C293: ', | G293: ', | H293: =IF(Sheet1!K301, 1, 0) -> 0 | I293: ,' | K293: ',' | M293: ','
A294: (' | C294: ', | G294: ', | H294: =IF(Sheet1!K302, 1, 0) -> 0 | I294: ,' | K294: ',' | M294: ','
A295: (' | C295: ', | G295: ', | H295: =IF(Sheet1!K303, 1, 0) -> 0 | I295: ,' | K295: ',' | M295: ','
A296: (' | C296: ', | G296: ', | H296: =IF(Sheet1!K304, 1, 0) -> 0 | I296: ,' | K296: ',' | M296: ','
A297: (' | C297: ', | G297: ', | H297: =IF(Sheet1!K305, 1, 0) -> 0 | I297: ,' | K297: ',' | M297: ','
A298: (' | C298: ', | G298: ', | H298: =IF(Sheet1!K306, 1, 0) -> 0 | I298: ,' | K298: ',' | M298: ','
A299: (' | C299: ', | G299: ', | H299: =IF(Sheet1!K307, 1, 0) -> 0 | I299: ,' | K299: ',' | M299: ','
A300: (' | C300: ', | G300: ', | H300: =IF(Sheet1!K308, 1, 0) -> 0 | I300: ,' | K300: ',' | M300: ','
A301: (' | C301: ', | G301: ', | H301: =IF(Sheet1!K309, 1, 0) -> 0 | I301: ,' | K301: ',' | M301: ','
A302: (' | C302: ', | G302: ', | H302: =IF(Sheet1!K310, 1, 0) -> 0 | I302: ,' | K302: ',' | M302: ','
A303: (' | C303: ', | G303: ', | H303: =IF(Sheet1!K311, 1, 0) -> 0 | I303: ,' | K303: ',' | M303: ','
... A1000: (' | C1000: ', | G1000: ', | H1000: =IF(Sheet1!K1008, 1, 0) -> 0 | I1000: ,' | K1000: ',' | M1000: ','
